<?xml version="1.0"?>
<robot xmlns:xacro="http://www.ros.org/wiki/xacro" >

    <xacro:include filename="inertial_macros.xacro"/>
    <xacro:include filename="materials.xacro"/>


    <!-- base link-->
    <link name="base_link">
        
    </link>
    <!-- base foot print link -->
    <joint name="base_footprint_joint" type="fixed">
        <parent link="base_link"/>
        <child link="base_footprint"/>
        <origin xyz="0 0 0" rpy="0 0 0"/>
    </joint>    
        
    <link name="base_footprint">
        
    </link>

    <joint name="chassis_joint" type="fixed">
        <parent link="base_link"/>
        <child link="chassis"/>
        <origin xyz="0 0 0.4" />
    </joint>

    <!-- chassis link -->
    <link name="chassis">
        <visual>
            <origin xyz="0 0 0" />
            <geometry>
                <box size="0.6 0.3 0.15"/>
            </geometry>
            <material name="chassis" />
        </visual>

        <xacro:inertial_box mass="0.5" x="0.3" y="0.3" z="0.15">
            <origin xyz="0 0 0" rpy="0 0 0"/>
        </xacro:inertial_box>
    </link>    


    <joint name="bottom_left_wheel_joint" type="continuous">
        <parent link="chassis" />
        <child link="bottom_left_wheel" />        
        <origin xyz="-0.2 0.2 -0.08" rpy="-${pi/2} 0 0"/>
        <axis xyz="0 0 1"/>
    </joint>
    
    <!-- bottom left wheel link -->
    <link name="bottom_left_wheel">
        <visual>
            <geometry>
                <cylinder radius="0.1" length="0.08"/>
            </geometry>
            <material name="wheel"/>
        </visual>

        <collision>
            <geometry>
                <cylinder radius="0.1" length="0.08"/>
            </geometry>
        </collision>

        <xacro:inertial_cylinder mass="0.1" length="0.1" radius="0.05">
            <origin xyz="0.0 0.0 0.0" rpy="0.0 0.0 0.0"/>
        </xacro:inertial_cylinder>    
    </link>
    
    <joint name="bottom_right_wheel_joint" type="continuous">
        <parent link="chassis" />
        <child link="bottom_right_wheel" />        
        <origin xyz="-0.2 -0.2 -0.08" rpy="${pi/2} 0 0"/>
        <axis xyz="0 0 -1"/>
    </joint>
    
    <!-- bottom right wheel link -->
    <link name="bottom_right_wheel">
        <visual>
            <geometry>
                <cylinder radius="0.1" length="0.08"/>
            </geometry>
            <material name="wheel"/>
        </visual>
        
        <collision>
            <geometry>
                <cylinder radius="0.1" length="0.08"/>
            </geometry>
        </collision>

        <xacro:inertial_cylinder mass="0.1" length="0.1" radius="0.05">
            <origin xyz="0.0 0.0 0.0" rpy="0.0 0.0 0.0"/>
        </xacro:inertial_cylinder>
    </link>

    <!-- top left wheel link -->
    <joint name="top_left_steer_joint" type="revolute">
        <parent link="chassis" />
        <child link="top_left_steer_link" />        
        <origin xyz="0.2 0.155 -0.08" rpy="0 0 0"/>
        <axis xyz="0.0 0.0 1.0"/>
        <limit lower="-${pi/6}" upper="${pi/6}" effort="3.0" velocity="10.0"/>
    </joint>

    <joint name="top_left_wheel_joint" type="continuous">
        <parent link="top_left_steer_link" />
        <child link="top_left_wheel" />        
        <origin xyz="0 0.05 0" rpy="-${pi/2} 0 0"/>
        <axis xyz="0 0 1"/>
    </joint>

    <link name="top_left_steer_link">
        <visual>
            <geometry>
                <cylinder radius="0.005" length="0.05"/>
            </geometry>
        </visual>
        <collision>
            <geometry>
                <cylinder radius="0.005" length="0.05"/>
            </geometry>
        </collision>
        <xacro:inertial_cylinder mass="0.01" length="0.05" radius="0.05">
            <origin xyz="0.0 0.0 0.0" rpy="0.0 0.0 0.0"/>
        </xacro:inertial_cylinder>
    </link>

    <link name="top_left_wheel">
        <visual>
            <geometry>
                <cylinder radius="0.1" length="0.08"/>
            </geometry>
            <material name="wheel"/>
        </visual>

        <collision>
            <geometry>
                <cylinder radius="0.1" length="0.08"/>
            </geometry>
        </collision>

        <xacro:inertial_cylinder mass="0.1" length="0.5" radius="0.05">
            <origin xyz="0.0 0.0 0.0" rpy="0.0 0.0 0.0"/>
        </xacro:inertial_cylinder>    
    </link>


    <!-- top right wheel link -->
    <joint name="top_right_steer_joint" type="revolute">
        <parent link="chassis" />
        <child link="top_right_steer_link" />        
        <origin xyz="0.2 -0.155 -0.08" rpy="0 0 0"/>
        <axis xyz="0.0 0.0 1.0"/>
        <limit lower="-${pi/6}" upper="${pi/6}" effort="3.0" velocity="10.0"/>
    </joint>

    <joint name="top_right_wheel_joint" type="continuous">
        <parent link="top_right_steer_link" />
        <child link="top_right_wheel" />        
        <origin xyz="0 -0.05 0" rpy="${pi/2} 0 0"/>
        <axis xyz="0 0 -1"/>
    </joint>
    
    <link name="top_right_steer_link">
        <visual>
            <geometry>
                <cylinder radius="0.005" length="0.05"/>
            </geometry>
        </visual>
        <collision>
            <geometry>
                <cylinder radius="0.005" length="0.05"/>
            </geometry>
        </collision>
        <xacro:inertial_cylinder mass="0.01" length="0.05" radius="0.05">
            <origin xyz="0.0 0.0 0.0" rpy="0.0 0.0 0.0"/>
        </xacro:inertial_cylinder>
    </link>

    <link name="top_right_wheel">
        <visual>
            <geometry>
                <cylinder radius="0.1" length="0.08"/>
            </geometry>
            <material name="wheel"/>
        </visual>
        
        <collision>
            <geometry>
                <cylinder radius="0.1" length="0.08"/>
            </geometry>
        </collision>

        <xacro:inertial_cylinder mass="0.1" length="0.5" radius="0.05">
            <origin xyz="0.0 0.0 0.0" rpy="0.0 0.0 0.0"/>
        </xacro:inertial_cylinder>
    </link>




</robot>